Workbook

Sheet Sheet4
A1: Age | B1: (All)
A3: Row Labels | B3: Sum of TreatmentCost
A4: Arthritis | B4: 113539
A5: Asthma | B5: 103544
A6: Cancer | B6: 112219
A7: COPD | B7: 110654
A8: Diabetes | B8: 104604
A9: Heart Disease | B9: 149681
A10: Hypertension | B10: 163926
A11: Kidney Disease | B11: 63290
A12: Liver Disease | B12: 155376
A13: Stroke | B13: 144149
A14: Grand Total | B14: 1220982

Sheet patients
A1: PatientID | B1: Name | C1: Age | D1: Gender | E1: DiagnosisID | F1: AdmissionDate | G1: DischargeDate | H1: OutcomeID | I1: TreatmentCost | J1: Dignosis name | K1: outcomename | L1: Days of digno | M1: Abnormal blood sugar flage | N1: risk raet
A2: 1 | B2: Edward Montes | C2: 68 | D2: M | E2: 2 | F2: 45738 | G2: 45751 | H2: 1 | I2: 4443 | J2: =VLOOKUP(E2,Dignosis!$A$1:$B$11,2,) -> Diabetes | K2: =VLOOKUP(H2,patients!$A$1:$B$4,2,) -> Edward Montes | L2: =_xlfn.DAYS(G2,F2) -> 13 | N2: =IF(OR(C2<65,H2<1),"high risk","low risk") -> low risk
A3: 2 | B3: Jessica Zimmerman | C3: 81 | D3: M | E3: 2 | F3: 45747 | G3: 45749 | H3: 2 | I3: 4265 | J3: =VLOOKUP(E3,Dignosis!$A$1:$B$11,2,) -> Diabetes | K3: =VLOOKUP(H3,patients!$A$1:$B$4,2,) -> Jessica Zimmerman | L3: =_xlfn.DAYS(G3,F3) -> 2 | N3: =IF(OR(C3<65,H3<1),"high risk","low risk") -> low risk
A4: 3 | B4: Gina Alexander | C4: 58 | D4: M | E4: 6 | F4: 45665 | G4: 45729 | H4: 1 | I4: 4188 | J4: =VLOOKUP(E4,Dignosis!$A$1:$B$11,2,) -> COPD | K4: =VLOOKUP(H4,patients!$A$1:$B$4,2,) -> Edward Montes | L4: =_xlfn.DAYS(G4,F4) -> 64 | M4: =IF(VLOOKUP(A4,labs!A4:E203,3,FALSE)>120,"high",) -> high | N4: =IF(OR(C4<65,H4<1),"high risk","low risk") -> high risk
A5: 4 | B5: Lori Green | C5: 44 | D5: F | E5: 3 | F5: 45750 | G5: 45752 | H5: 1 | I5: 9783 | J5: =VLOOKUP(E5,Dignosis!$A$1:$B$11,2,) -> Heart Disease | K5: =VLOOKUP(H5,patients!$A$1:$B$4,2,) -> Edward Montes | L5: =_xlfn.DAYS(G5,F5) -> 2 | M5: =IF(VLOOKUP(A5,labs!A5:E204,3,FALSE)>120,"high",) -> high | N5: =IF(OR(C5<65,H5<1),"high risk","low risk") -> high risk
A6: 5 | B6: Jack Logan | C6: 72 | D6: F | E6: 9 | F6: 45811 | G6: 45812 | H6: 1 | I6: 5005 | J6: =VLOOKUP(E6,Dignosis!$A$1:$B$11,2,) -> Kidney Disease | K6: =VLOOKUP(H6,patients!$A$1:$B$4,2,) -> Edward Montes | L6: =_xlfn.DAYS(G6,F6) -> 1 | M6: =IF(VLOOKUP(A6,labs!A6:E205,3,FALSE)>120,"high",) -> high | N6: =IF(OR(C6<65,H6<1),"high risk","low risk") -> low risk
A7: 6 | B7: Melinda Robinson | C7: 37 | D7: F | E7: 4 | F7: 45747 | G7: 45752 | H7: 1 | I7: 5281 | J7: =VLOOKUP(E7,Dignosis!$A$1:$B$11,2,) -> Asthma | K7: =VLOOKUP(H7,patients!$A$1:$B$4,2,) -> Edward Montes | L7: =_xlfn.DAYS(G7,F7) -> 5 | M7: =IF(VLOOKUP(A7,labs!A7:E206,3,FALSE)>120,"high",) -> high | N7: =IF(OR(C7<65,H7<1),"high risk","low risk") -> high risk
A8: 7 | B8: Sherry Robinson | C8: 50 | D8: F | E8: 1 | F8: 45819 | G8: 45843 | H8: 2 | I8: 2984 | J8: =VLOOKUP(E8,Dignosis!$A$1:$B$11,2,) -> Hypertension | K8: =VLOOKUP(H8,patients!$A$1:$B$4,2,) -> Jessica Zimmerman | L8: =_xlfn.DAYS(G8,F8) -> 24 | M8: =IF(VLOOKUP(A8,labs!A8:E207,3,FALSE)>120,"high",) -> high | N8: =IF(OR(C8<65,H8<1),"high risk","low risk") -> high risk
A9: 8 | B9: James Watts | C9: 68 | D9: M | E9: 4 | F9: 45772 | G9: 45827 | H9: 1 | I9: 9136 | J9: =VLOOKUP(E9,Dignosis!$A$1:$B$11,2,) -> Asthma | K9: =VLOOKUP(H9,patients!$A$1:$B$4,2,) -> Edward Montes | L9: =_xlfn.DAYS(G9,F9) -> 55 | M9: =IF(VLOOKUP(A9,labs!A9:E208,3,FALSE)>120,"high",) -> high | N9: =IF(OR(C9<65,H9<1),"high risk","low risk") -> low risk
A10: 9 | B10: Jeanne Butler | C10: 87 | D10: F | E10: 1 | F10: 45762 | G10: 45764 | H10: 2 | I10: 9790 | J10: =VLOOKUP(E10,Dignosis!$A$1:$B$11,2,) -> Hypertension | K10: =VLOOKUP(H10,patients!$A$1:$B$4,2,) -> Jessica Zimmerman | L10: =_xlfn.DAYS(G10,F10) -> 2 | M10: =IF(VLOOKUP(A10,labs!A10:E209,3,FALSE)>120,"high",) -> high | N10: =IF(OR(C10<65,H10<1),"high risk","low risk") -> low risk
A11: 10 | B11: Benjamin Rogers | C11: 48 | D11: M | E11: 5 | F11: 45792 | G11: 45796 | H11: 2 | I11: 3639 | J11: =VLOOKUP(E11,Dignosis!$A$1:$B$11,2,) -> Stroke | K11: =VLOOKUP(H11,patients!$A$1:$B$4,2,) -> Jessica Zimmerman | L11: =_xlfn.DAYS(G11,F11) -> 4 | M11: =IF(VLOOKUP(A11,labs!A11:E210,3,FALSE)>120,"high",) -> high | N11: =IF(OR(C11<65,H11<1),"high risk","low risk") -> high risk
A12: 11 | B12: Carol Sanchez | C12: 52 | D12: M | E12: 4 | F12: 45715 | G12: 45765 | H12: 3 | I12: 2827 | J12: =VLOOKUP(E12,Dignosis!$A$1:$B$11,2,) -> Asthma | K12: =VLOOKUP(H12,patients!$A$1:$B$4,2,) -> Gina Alexander | L12: =_xlfn.DAYS(G12,F12) -> 50 | M12: =IF(VLOOKUP(A12,labs!A12:E211,3,FALSE)>120,"high",) -> high | N12: =IF(OR(C12<65,H12<1),"high risk","low risk") -> high risk
A13: 12 | B13: Stacy Clark | C13: 40 | D13: F | E13: 8 | F13: 45771 | G13: 45795 | H13: 2 | I13: 4730 | J13: =VLOOKUP(E13,Dignosis!$A$1:$B$11,2,) -> Arthritis | K13: =VLOOKUP(H13,patients!$A$1:$B$4,2,) -> Jessica Zimmerman | L13: =_xlfn.DAYS(G13,F13) -> 24 | M13: =IF(VLOOKUP(A13,labs!A13:E212,3,FALSE)>120,"high",) -> high | N13: =IF(OR(C13<65,H13<1),"high risk","low risk") -> high risk
A14: 13 | B14: Kimberly Chase | C14: 40 | D14: F | E14: 8 | F14: 45732 | G14: 45815 | H14: 3 | I14: 5531 | J14: =VLOOKUP(E14,Dignosis!$A$1:$B$11,2,) -> Arthritis | K14: =VLOOKUP(H14,patients!$A$1:$B$4,2,) -> Gina Alexander | L14: =_xlfn.DAYS(G14,F14) -> 83 | M14: =IF(VLOOKUP(A14,labs!A14:E213,3,FALSE)>120,"high",) -> high | N14: =IF(OR(C14<65,H14<1),"high risk","low risk") -> high risk
A15: 14 | B15: Cody Ryan | C15: 53 | D15: F | E15: 7 | F15: 45814 | G15: 45818 | H15: 2 | I15: 9147 | J15: =VLOOKUP(E15,Dignosis!$A$1:$B$11,2,) -> Cancer | K15: =VLOOKUP(H15,patients!$A$1:$B$4,2,) -> Jessica Zimmerman | L15: =_xlfn.DAYS(G15,F15) -> 4 | M15: =IF(VLOOKUP(A15,labs!A15:E214,3,FALSE)>120,"high",) -> high | N15: =IF(OR(C15<65,H15<1),"high risk","low risk") -> high risk
... A201: 200 | B201: Gregory Bates | C201: 61 | D201: F | E201: 3 | F201: 45668 | G201: 45725 | H201: 3 | I201: 5983 | J201: =VLOOKUP(E201,Dignosis!$A$1:$B$11,2,) -> Heart Disease | K201: =VLOOKUP(H201,patients!$A$1:$B$4,2,) -> Gina Alexander | L201: =_xlfn.DAYS(G201,F201) -> 57 | M201: =IF(VLOOKUP(A201,labs!A201:E400,3,FALSE)>120,"high",) -> high | N201: =IF(OR(C201<65,H201<1),"high risk","low risk") -> high risk

Sheet labs
A1: LabID | B1: PatientID | C1: TestName | D1: Result | E1: NormalRange | F1: LOW limit | G1: High limit
A2: 1 | B2: 196 | C2: Blood Pressure | D2: 89 | E2: 150-200 | F2: {=_xlfn.TEXTSPLIT(E2,"-")} -> 150 | G2: 200 | H2: =IF(D2 < F2, "Low", IF(D2 > G2, "High", "Normal")) -> Low
A3: 2 | B3: 165 | C3: Cholesterol | D3: 270.2 | E3: 13-17 | F3: {=_xlfn.TEXTSPLIT(E3,"-")} -> 13 | G3: 17 | H3: =IF(D3 < F3, "Low", IF(D3 > G3, "High", "Normal")) -> Low
A4: 3 | B4: 182 | C4: Blood Pressure | D4: 268 | E4: 0.6-1.2 | F4: {=_xlfn.TEXTSPLIT(E4,"-")} -> 0.6 | G4: 1.2 | H4: =IF(D4 < F4, "Low", IF(D4 > G4, "High", "Normal")) -> Low
A5: 4 | B5: 142 | C5: Cholesterol | D5: 57.3 | E5: 150-200 | F5: {=_xlfn.TEXTSPLIT(E5,"-")} -> 150 | G5: 200 | H5: =IF(D5 < F5, "Low", IF(D5 > G5, "High", "Normal")) -> Low
A6: 5 | B6: 55 | C6: Blood Sugar | D6: 256.5 | E6: 120/80 | F6: {=_xlfn.TEXTSPLIT(E6,"/")} -> 120 | G6: 80 | H6: =IF(D6 < F6, "Low", IF(D6 > G6, "High", "Normal")) -> Low
A7: 6 | B7: 176 | C7: Creatinine | D7: 82.2 | E7: 120/80 | F7: {=_xlfn.TEXTSPLIT(E7,"/")} -> 120 | G7: 80 | H7: =IF(D7 < F7, "Low", IF(D7 > G7, "High", "Normal")) -> Low
A8: 7 | B8: 7 | C8: Blood Pressure | D8: 133.8 | E8: 150-200 | F8: {=_xlfn.TEXTSPLIT(E8,"-")} -> 150 | G8: 200 | H8: =IF(D8 < F8, "Low", IF(D8 > G8, "High", "Normal")) -> Low
A9: 8 | B9: 74 | C9: Hemoglobin | D9: 235.9 | E9: 0.6-1.2 | F9: {=_xlfn.TEXTSPLIT(E9,"-")} -> 0.6 | G9: 1.2 | H9: =IF(D9 < F9, "Low", IF(D9 > G9, "High", "Normal")) -> Low
A10: 9 | B10: 7 | C10: Hemoglobin | D10: 90.2 | E10: 20-50 | F10: {=_xlfn.TEXTSPLIT(E10,"-")} -> 20 | G10: 50 | H10: =IF(D10 < F10, "Low", IF(D10 > G10, "High", "Normal")) -> Low
A11: 10 | B11: 161 | C11: Vitamin D | D11: 254.5 | E11: 13-17 | F11: {=_xlfn.TEXTSPLIT(E11,"-")} -> 13 | G11: 17 | H11: =IF(D11 < F11, "Low", IF(D11 > G11, "High", "Normal")) -> Low
A12: 11 | B12: 151 | C12: Cholesterol | D12: 258 | E12: 120/80 | F12: {=_xlfn.TEXTSPLIT(E12,"/")} -> 120 | G12: 80 | H12: =IF(D12 < F12, "Low", IF(D12 > G12, "High", "Normal")) -> Low
A13: 12 | B13: 85 | C13: Blood Pressure | D13: 176.9 | E13: 20-50 | F13: {=_xlfn.TEXTSPLIT(E13,"-")} -> 20 | G13: 50 | H13: =IF(D13 < F13, "Low", IF(D13 > G13, "High", "Normal")) -> Low
A14: 13 | B14: 147 | C14: Vitamin D | D14: 51.6 | E14: 150-200 | F14: {=_xlfn.TEXTSPLIT(E14,"-")} -> 150 | G14: 200 | H14: =IF(D14 < F14, "Low", IF(D14 > G14, "High", "Normal")) -> Low
A15: 14 | B15: 112 | C15: Blood Pressure | D15: 121.8 | E15: 20-50 | F15: {=_xlfn.TEXTSPLIT(E15,"-")} -> 20 | G15: 50 | H15: =IF(D15 < F15, "Low", IF(D15 > G15, "High", "Normal")) -> Low
A16: 15 | B16: 125 | C16: Cholesterol | D16: 204.2 | E16: 70-120 | F16: {=_xlfn.TEXTSPLIT(E16,"-")} -> 70 | G16: 120 | H16: =IF(D16 < F16, "Low", IF(D16 > G16, "High", "Normal")) -> Low
A17: 16 | B17: 147 | C17: Hemoglobin | D17: 295.3 | E17: 120/80 | F17: {=_xlfn.TEXTSPLIT(E17,"/")} -> 120 | G17: 80 | H17: =IF(D17 < F17, "Low", IF(D17 > G17, "High", "Normal")) -> Low
A18: 17 | B18: 36 | C18: Blood Sugar | D18: 208 | E18: 150-200 | F18: {=_xlfn.TEXTSPLIT(E18,"-")} -> 150 | G18: 200 | H18: =IF(D18 < F18, "Low", IF(D18 > G18, "High", "Normal")) -> Low
A19: 18 | B19: 29 | C19: Hemoglobin | D19: 115 | E19: 13-17 | F19: {=_xlfn.TEXTSPLIT(E19,"-")} -> 13 | G19: 17 | H19: =IF(D19 < F19, "Low", IF(D19 > G19, "High", "Normal")) -> Low
A20: 19 | B20: 188 | C20: Vitamin D | D20: 208.5 | E20: 0.6-1.2 | F20: {=_xlfn.TEXTSPLIT(E20,"-")} -> 0.6 | G20: 1.2 | H20: =IF(D20 < F20, "Low", IF(D20 > G20, "High", "Normal")) -> Low
A21: 20 | B21: 82 | C21: Creatinine | D21: 185 | E21: 150-200 | F21: {=_xlfn.TEXTSPLIT(E21,"-")} -> 150 | G21: 200 | H21: =IF(D21 < F21, "Low", IF(D21 > G21, "High", "Normal")) -> Low
A22: 21 | B22: 2 | C22: Blood Sugar | D22: 245 | E22: 13-17 | F22: {=_xlfn.TEXTSPLIT(E22,"-")} -> 13 | G22: 17 | H22: =IF(D22 < F22, "Low", IF(D22 > G22, "High", "Normal")) -> Low
A23: 22 | B23: 129 | C23: Vitamin D | D23: 76.7 | E23: 0.6-1.2 | F23: {=_xlfn.TEXTSPLIT(E23,"-")} -> 0.6 | G23: 1.2 | H23: =IF(D23 < F23, "Low", IF(D23 > G23, "High", "Normal")) -> Low
A24: 23 | B24: 47 | C24: Cholesterol | D24: 240.3 | E24: 0.6-1.2 | F24: {=_xlfn.TEXTSPLIT(E24,"-")} -> 0.6 | G24: 1.2 | H24: =IF(D24 < F24, "Low", IF(D24 > G24, "High", "Normal")) -> Low
A25: 24 | B25: 197 | C25: Blood Sugar | D25: 185.3 | E25: 150-200 | F25: {=_xlfn.TEXTSPLIT(E25,"-")} -> 150 | G25: 200 | H25: =IF(D25 < F25, "Low", IF(D25 > G25, "High", "Normal")) -> Low
A26: 25 | B26: 148 | C26: Vitamin D | D26: 290.7 | E26: 20-50 | F26: {=_xlfn.TEXTSPLIT(E26,"-")} -> 20 | G26: 50 | H26: =IF(D26 < F26, "Low", IF(D26 > G26, "High", "Normal")) -> Low
A27: 26 | B27: 11 | C27: Cholesterol | D27: 135.5 | E27: 20-50 | F27: {=_xlfn.TEXTSPLIT(E27,"-")} -> 20 | G27: 50 | H27: =IF(D27 < F27, "Low", IF(D27 > G27, "High", "Normal")) -> Low
A28: 27 | B28: 130 | C28: Hemoglobin | D28: 208.2 | E28: 0.6-1.2 | F28: {=_xlfn.TEXTSPLIT(E28,"-")} -> 0.6 | G28: 1.2 | H28: =IF(D28 < F28, "Low", IF(D28 > G28, "High", "Normal")) -> Low
A29: 28 | B29: 195 | C29: Creatinine | D29: 283 | E29: 20-50 | F29: {=_xlfn.TEXTSPLIT(E29,"-")} -> 20 | G29: 50 | H29: =IF(D29 < F29, "Low", IF(D29 > G29, "High", "Normal")) -> Low
... A40: 39 | B40: 86 | C40: Blood Pressure | D40: 61.4 | E40: 70-120 | F40: {=_xlfn.TEXTSPLIT(E40,"-")} -> 70 | G40: 120 | H40: =IF(D40 < F40, "Low", IF(D40 > G40, "High", "Normal")) -> Low
A41: 40 | B41: 108 | C41: Creatinine | D41: 267.9 | E41: 120/80 | F41: {=_xlfn.TEXTSPLIT(E41,"/")} -> 120 | G41: 80 | H41: =IF(D41 < F41, "Low", IF(D41 > G41, "High", "Normal")) -> Low
A42: 41 | B42: 24 | C42: Hemoglobin | D42: 293.4 | E42: 70-120 | F42: {=_xlfn.TEXTSPLIT(E42,"-")} -> 70 | G42: 120 | H42: =IF(D42 < F42, "Low", IF(D42 > G42, "High", "Normal")) -> Low
A43: 42 | B43: 81 | C43: Vitamin D | D43: 292.2 | E43: 70-120 | F43: {=_xlfn.TEXTSPLIT(E43,"-")} -> 70 | G43: 120 | H43: =IF(D43 < F43, "Low", IF(D43 > G43, "High", "Normal")) -> Low
A44: 43 | B44: 158 | C44: Creatinine | D44: 237.4 | E44: 13-17 | F44: {=_xlfn.TEXTSPLIT(E44,"-")} -> 13 | G44: 17 | H44: =IF(D44 < F44, "Low", IF(D44 > G44, "High", "Normal")) -> Low
A45: 44 | B45: 120 | C45: Blood Sugar | D45: 82.5 | E45: 150-200 | F45: {=_xlfn.TEXTSPLIT(E45,"-")} -> 150 | G45: 200 | H45: =IF(D45 < F45, "Low", IF(D45 > G45, "High", "Normal")) -> Low
A46: 45 | B46: 59 | C46: Vitamin D | D46: 239.6 | E46: 120/80 | F46: {=_xlfn.TEXTSPLIT(E46,"/")} -> 120 | G46: 80 | H46: =IF(D46 < F46, "Low", IF(D46 > G46, "High", "Normal")) -> Low
A47: 46 | B47: 128 | C47: Creatinine | D47: 56.1 | E47: 20-50 | F47: {=_xlfn.TEXTSPLIT(E47,"-")} -> 20 | G47: 50 | H47: =IF(D47 < F47, "Low", IF(D47 > G47, "High", "Normal")) -> Low
A48: 47 | B48: 114 | C48: Vitamin D | D48: 55.5 | E48: 20-50 | F48: {=_xlfn.TEXTSPLIT(E48,"-")} -> 20 | G48: 50 | H48: =IF(D48 < F48, "Low", IF(D48 > G48, "High", "Normal")) -> Low
A49: 48 | B49: 115 | C49: Hemoglobin | D49: 130.9 | E49: 70-120 | F49: {=_xlfn.TEXTSPLIT(E49,"-")} -> 70 | G49: 120 | H49: =IF(D49 < F49, "Low", IF(D49 > G49, "High", "Normal")) -> Low
A50: 49 | B50: 14 | C50: Blood Sugar | D50: 172.2 | E50: 13-17 | F50: {=_xlfn.TEXTSPLIT(E50,"-")} -> 13 | G50: 17 | H50: =IF(D50 < F50, "Low", IF(D50 > G50, "High", "Normal")) -> Low
...

Sheet outcomes
A1: OutcomeID | B1: OutcomeName
A2: 1 | B2: Recovered
A3: 2 | B3: Complicated
A4: 3 | B4: Deceased

Sheet Dignosis
A1: DiagnosisID | B1: DiagnosisName
A2: 1 | B2: Hypertension
A3: 2 | B3: Diabetes
A4: 3 | B4: Heart Disease
A5: 4 | B5: Asthma
A6: 5 | B6: Stroke
A7: 6 | B7: COPD
A8: 7 | B8: Cancer
A9: 8 | B9: Arthritis
A10: 9 | B10: Kidney Disease
A11: 10 | B11: Liver Disease
